{"uuid": "246c9de4-62fc-4afe-8699-9702cc6c23b4", "children": ["b977687e-ab00-4631-9938-1b50dd431f02"], "befores": [{"name": "test_setup", "status": "broken", "statusDetails": {"message": "urllib3.exceptions.MaxRetryError: HTTPConnectionPool(host='127.0.0.1', port=51468): Max retries exceeded with url: /session/c8410b59790a3817ca99a3c9254f794e/url (Caused by NewConnectionError('<urllib3.connection.HTTPConnection object at 0x00000140E1556B10>: Failed to establish a new connection: [WinError 10061] No connection could be made because the target machine actively refused it'))\n", "trace": "  File \"C:\\Users\\takia\\AppData\\Local\\Programs\\Python\\Python311\\Lib\\site-packages\\pluggy\\_callers.py\", line 39, in _multicall\n    res = hook_impl.function(*args)\n          ^^^^^^^^^^^^^^^^^^^^^^^^^\n  File \"C:\\Users\\takia\\AppData\\Local\\Programs\\Python\\Python311\\Lib\\site-packages\\_pytest\\fixtures.py\", line 1128, in pytest_fixture_setup\n    result = call_fixture_func(fixturefunc, request, kwargs)\n             ^^^^^^^^^^^^^^^^^^^^^^^^^^^^^^^^^^^^^^^^^^^^^^^\n  File \"C:\\Users\\takia\\AppData\\Local\\Programs\\Python\\Python311\\Lib\\site-packages\\_pytest\\fixtures.py\", line 900, in call_fixture_func\n    fixture_result = next(generator)\n                     ^^^^^^^^^^^^^^^\n  File \"C:\\Users\\takia\\Documents\\workspace\\selenium-python-automation\\test\\test_login.py\", line 12, in test_setup\n    driver.get(url)\n  File \"C:\\Users\\takia\\AppData\\Local\\Programs\\Python\\Python311\\Lib\\site-packages\\selenium\\webdriver\\remote\\webdriver.py\", line 333, in get\n    self.execute(Command.GET, {'url': url})\n  File \"C:\\Users\\takia\\AppData\\Local\\Programs\\Python\\Python311\\Lib\\site-packages\\selenium\\webdriver\\remote\\webdriver.py\", line 319, in execute\n    response = self.command_executor.execute(driver_command, params)\n               ^^^^^^^^^^^^^^^^^^^^^^^^^^^^^^^^^^^^^^^^^^^^^^^^^^^^^\n  File \"C:\\Users\\takia\\AppData\\Local\\Programs\\Python\\Python311\\Lib\\site-packages\\selenium\\webdriver\\remote\\remote_connection.py\", line 374, in execute\n    return self._request(command_info[0], url, body=data)\n           ^^^^^^^^^^^^^^^^^^^^^^^^^^^^^^^^^^^^^^^^^^^^^^\n  File \"C:\\Users\\takia\\AppData\\Local\\Programs\\Python\\Python311\\Lib\\site-packages\\selenium\\webdriver\\remote\\remote_connection.py\", line 397, in _request\n    resp = self._conn.request(method, url, body=body, headers=headers)\n           ^^^^^^^^^^^^^^^^^^^^^^^^^^^^^^^^^^^^^^^^^^^^^^^^^^^^^^^^^^^\n  File \"C:\\Users\\takia\\AppData\\Local\\Programs\\Python\\Python311\\Lib\\site-packages\\urllib3\\request.py\", line 78, in request\n    return self.request_encode_body(\n           ^^^^^^^^^^^^^^^^^^^^^^^^^\n  File \"C:\\Users\\takia\\AppData\\Local\\Programs\\Python\\Python311\\Lib\\site-packages\\urllib3\\request.py\", line 170, in request_encode_body\n    return self.urlopen(method, url, **extra_kw)\n           ^^^^^^^^^^^^^^^^^^^^^^^^^^^^^^^^^^^^^\n  File \"C:\\Users\\takia\\AppData\\Local\\Programs\\Python\\Python311\\Lib\\site-packages\\urllib3\\poolmanager.py\", line 376, in urlopen\n    response = conn.urlopen(method, u.request_uri, **kw)\n               ^^^^^^^^^^^^^^^^^^^^^^^^^^^^^^^^^^^^^^^^^\n  File \"C:\\Users\\takia\\AppData\\Local\\Programs\\Python\\Python311\\Lib\\site-packages\\urllib3\\connectionpool.py\", line 815, in urlopen\n    return self.urlopen(\n           ^^^^^^^^^^^^^\n  File \"C:\\Users\\takia\\AppData\\Local\\Programs\\Python\\Python311\\Lib\\site-packages\\urllib3\\connectionpool.py\", line 815, in urlopen\n    return self.urlopen(\n           ^^^^^^^^^^^^^\n  File \"C:\\Users\\takia\\AppData\\Local\\Programs\\Python\\Python311\\Lib\\site-packages\\urllib3\\connectionpool.py\", line 815, in urlopen\n    return self.urlopen(\n           ^^^^^^^^^^^^^\n  File \"C:\\Users\\takia\\AppData\\Local\\Programs\\Python\\Python311\\Lib\\site-packages\\urllib3\\connectionpool.py\", line 787, in urlopen\n    retries = retries.increment(\n              ^^^^^^^^^^^^^^^^^^\n  File \"C:\\Users\\takia\\AppData\\Local\\Programs\\Python\\Python311\\Lib\\site-packages\\urllib3\\util\\retry.py\", line 592, in increment\n    raise MaxRetryError(_pool, url, error or ResponseError(cause))\n"}, "start": 1673064748815, "stop": 1673064756941}], "start": 1673064748815, "stop": 1673064757342}